<?xml version="1.0"?>
<robot name="linear_actuator">
    <!-- Base Link -->
    <link name="base_link">
        <visual>
            <geometry>
                <box size="0.1 0.1 0.05"/>
            </geometry>
            <material name="gray">
                <color rgba="0.5 0.5 0.5 1"/>
            </material>
        </visual>
        <collision>
            <geometry>
                <box size="0.1 0.1 0.05"/>
            </geometry>
        </collision>
        <inertial>
            <mass value="1.0"/>
            <inertia ixx="0.001" ixy="0.0" ixz="0.0" 
                     iyy="0.001" iyz="0.0" 
                     izz="0.001"/>
        </inertial>
    </link>

    <!-- Sliding Link -->
    <link name="slider_link">
        <visual>
            <geometry>
                <cylinder radius="0.02" length="0.3"/>
            </geometry>
            <material name="blue">
                <color rgba="0.0 0.0 0.8 1"/>
            </material>
        </visual>
        <collision>
            <geometry>
                <cylinder radius="0.02" length="0.3"/>
            </geometry>
        </collision>
        <inertial>
            <mass value="0.5"/>
            <inertia ixx="0.001" ixy="0.0" ixz="0.0" 
                     iyy="0.001" iyz="0.0" 
                     izz="0.0001"/>
        </inertial>
    </link>

    <!-- Prismatic Joint -->
    <joint name="slider_joint" type="prismatic">
        <parent link="base_link"/>
        <child link="slider_link"/>
        <origin xyz="0 0 0.175" rpy="0 0 0"/>
        <axis xyz="0 0 1"/>
        <limit effort="100.0" lower="0.0" upper="0.3" velocity="1.0"/>
        <dynamics damping="0.7" friction="0.0"/>
    </joint>

    <!-- Transmission for control -->
    <transmission name="slider_trans">
        <type>transmission_interface/SimpleTransmission</type>
        <joint name="slider_joint">
            <hardwareInterface>hardware_interface/PositionJointInterface</hardwareInterface>
        </joint>
        <actuator name="slider_motor">
            <hardwareInterface>hardware_interface/PositionJointInterface</hardwareInterface>
            <mechanicalReduction>1</mechanicalReduction>
        </actuator>
    </transmission>
</robot>